[2025-08-23T08:27:45.575+0000] {taskinstance.py:1956} INFO - Dependencies all met for dep_context=non-requeueable deps ti=<TaskInstance: stock_data_pipeline.fetch_and_store_stock_data manual__2025-08-23T08:23:02.500845+00:00 [queued]>
[2025-08-23T08:27:45.595+0000] {taskinstance.py:1956} INFO - Dependencies all met for dep_context=requeueable deps ti=<TaskInstance: stock_data_pipeline.fetch_and_store_stock_data manual__2025-08-23T08:23:02.500845+00:00 [queued]>
[2025-08-23T08:27:45.596+0000] {taskinstance.py:2170} INFO - Starting attempt 2 of 2
[2025-08-23T08:27:45.628+0000] {taskinstance.py:2191} INFO - Executing <Task(PythonOperator): fetch_and_store_stock_data> on 2025-08-23 08:23:02.500845+00:00
[2025-08-23T08:27:45.649+0000] {standard_task_runner.py:60} INFO - Started process 435 to run task
[2025-08-23T08:27:45.657+0000] {standard_task_runner.py:87} INFO - Running: ['***', 'tasks', 'run', 'stock_data_pipeline', 'fetch_and_store_stock_data', 'manual__2025-08-23T08:23:02.500845+00:00', '--job-id', '9', '--raw', '--subdir', 'DAGS_FOLDER/stock_pipeline.py', '--cfg-path', '/tmp/tmpn7p49ps4']
[2025-08-23T08:27:45.663+0000] {standard_task_runner.py:88} INFO - Job 9: Subtask fetch_and_store_stock_data
[2025-08-23T08:27:45.719+0000] {logging_mixin.py:188} WARNING - /home/***/.local/lib/python3.8/site-packages/***/settings.py:194 DeprecationWarning: The sql_alchemy_conn option in [core] has been moved to the sql_alchemy_conn option in [database] - the old setting has been used, but please update your config.
[2025-08-23T08:27:45.821+0000] {task_command.py:423} INFO - Running <TaskInstance: stock_data_pipeline.fetch_and_store_stock_data manual__2025-08-23T08:23:02.500845+00:00 [running]> on host e4d6e44b2134
[2025-08-23T08:27:48.570+0000] {taskinstance.py:2480} INFO - Exporting env vars: AIRFLOW_CTX_DAG_OWNER='***' AIRFLOW_CTX_DAG_ID='stock_data_pipeline' AIRFLOW_CTX_TASK_ID='fetch_and_store_stock_data' AIRFLOW_CTX_EXECUTION_DATE='2025-08-23T08:23:02.500845+00:00' AIRFLOW_CTX_TRY_NUMBER='2' AIRFLOW_CTX_DAG_RUN_ID='manual__2025-08-23T08:23:02.500845+00:00'
[2025-08-23T08:27:48.574+0000] {fetch_stock_data.py:19} ERROR - Database connection failed: connection to server on socket "/var/run/postgresql/.s.PGSQL.5432" failed: No such file or directory
	Is the server running locally and accepting connections on that socket?

[2025-08-23T08:27:48.576+0000] {fetch_stock_data.py:45} ERROR - Error creating table: connection to server on socket "/var/run/postgresql/.s.PGSQL.5432" failed: No such file or directory
	Is the server running locally and accepting connections on that socket?

[2025-08-23T08:27:48.578+0000] {fetch_stock_data.py:146} ERROR - Pipeline failed: local variable 'conn' referenced before assignment
[2025-08-23T08:27:48.579+0000] {taskinstance.py:2698} ERROR - Task failed with exception
Traceback (most recent call last):
  File "/opt/airflow/dags/../scripts/fetch_stock_data.py", line 39, in create_stock_table_if_not_exists
    conn = get_db_connection()
  File "/opt/airflow/dags/../scripts/fetch_stock_data.py", line 16, in get_db_connection
    conn = psycopg2.connect(os.getenv('DB_CONNECTION'))
  File "/home/airflow/.local/lib/python3.8/site-packages/psycopg2/__init__.py", line 122, in connect
    conn = _connect(dsn, connection_factory=connection_factory, **kwasync)
psycopg2.OperationalError: connection to server on socket "/var/run/postgresql/.s.PGSQL.5432" failed: No such file or directory
	Is the server running locally and accepting connections on that socket?


During handling of the above exception, another exception occurred:

Traceback (most recent call last):
  File "/home/airflow/.local/lib/python3.8/site-packages/airflow/models/taskinstance.py", line 433, in _execute_task
    result = execute_callable(context=context, **execute_callable_kwargs)
  File "/home/airflow/.local/lib/python3.8/site-packages/airflow/operators/python.py", line 199, in execute
    return_value = self.execute_callable()
  File "/home/airflow/.local/lib/python3.8/site-packages/airflow/operators/python.py", line 216, in execute_callable
    return self.python_callable(*self.op_args, **self.op_kwargs)
  File "/opt/airflow/dags/../scripts/fetch_stock_data.py", line 132, in main
    create_stock_table_if_not_exists()
  File "/opt/airflow/dags/../scripts/fetch_stock_data.py", line 48, in create_stock_table_if_not_exists
    if conn:
UnboundLocalError: local variable 'conn' referenced before assignment
[2025-08-23T08:27:48.620+0000] {taskinstance.py:1138} INFO - Marking task as FAILED. dag_id=stock_data_pipeline, task_id=fetch_and_store_stock_data, execution_date=20250823T082302, start_date=20250823T082745, end_date=20250823T082748
[2025-08-23T08:27:48.659+0000] {standard_task_runner.py:107} ERROR - Failed to execute job 9 for task fetch_and_store_stock_data (local variable 'conn' referenced before assignment; 435)
[2025-08-23T08:27:48.759+0000] {local_task_job_runner.py:234} INFO - Task exited with return code 1
[2025-08-23T08:27:48.819+0000] {taskinstance.py:3280} INFO - 0 downstream tasks scheduled from follow-on schedule check
