[2025-08-23T08:27:15.292+0000] {taskinstance.py:1956} INFO - Dependencies all met for dep_context=non-requeueable deps ti=<TaskInstance: stock_data_pipeline.fetch_and_store_stock_data scheduled__2025-08-23T07:00:00+00:00 [queued]>
[2025-08-23T08:27:15.308+0000] {taskinstance.py:1956} INFO - Dependencies all met for dep_context=requeueable deps ti=<TaskInstance: stock_data_pipeline.fetch_and_store_stock_data scheduled__2025-08-23T07:00:00+00:00 [queued]>
[2025-08-23T08:27:15.310+0000] {taskinstance.py:2170} INFO - Starting attempt 2 of 2
[2025-08-23T08:27:15.333+0000] {taskinstance.py:2191} INFO - Executing <Task(PythonOperator): fetch_and_store_stock_data> on 2025-08-23 07:00:00+00:00
[2025-08-23T08:27:15.352+0000] {standard_task_runner.py:60} INFO - Started process 417 to run task
[2025-08-23T08:27:15.358+0000] {standard_task_runner.py:87} INFO - Running: ['***', 'tasks', 'run', 'stock_data_pipeline', 'fetch_and_store_stock_data', 'scheduled__2025-08-23T07:00:00+00:00', '--job-id', '7', '--raw', '--subdir', 'DAGS_FOLDER/stock_pipeline.py', '--cfg-path', '/tmp/tmpk3i8595i']
[2025-08-23T08:27:15.362+0000] {standard_task_runner.py:88} INFO - Job 7: Subtask fetch_and_store_stock_data
[2025-08-23T08:27:15.398+0000] {logging_mixin.py:188} WARNING - /home/***/.local/lib/python3.8/site-packages/***/settings.py:194 DeprecationWarning: The sql_alchemy_conn option in [core] has been moved to the sql_alchemy_conn option in [database] - the old setting has been used, but please update your config.
[2025-08-23T08:27:15.493+0000] {task_command.py:423} INFO - Running <TaskInstance: stock_data_pipeline.fetch_and_store_stock_data scheduled__2025-08-23T07:00:00+00:00 [running]> on host e4d6e44b2134
[2025-08-23T08:27:15.960+0000] {taskinstance.py:2480} INFO - Exporting env vars: AIRFLOW_CTX_DAG_OWNER='***' AIRFLOW_CTX_DAG_ID='stock_data_pipeline' AIRFLOW_CTX_TASK_ID='fetch_and_store_stock_data' AIRFLOW_CTX_EXECUTION_DATE='2025-08-23T07:00:00+00:00' AIRFLOW_CTX_TRY_NUMBER='2' AIRFLOW_CTX_DAG_RUN_ID='scheduled__2025-08-23T07:00:00+00:00'
[2025-08-23T08:27:15.963+0000] {fetch_stock_data.py:19} ERROR - Database connection failed: connection to server on socket "/var/run/postgresql/.s.PGSQL.5432" failed: No such file or directory
	Is the server running locally and accepting connections on that socket?

[2025-08-23T08:27:15.965+0000] {fetch_stock_data.py:45} ERROR - Error creating table: connection to server on socket "/var/run/postgresql/.s.PGSQL.5432" failed: No such file or directory
	Is the server running locally and accepting connections on that socket?

[2025-08-23T08:27:15.967+0000] {fetch_stock_data.py:146} ERROR - Pipeline failed: local variable 'conn' referenced before assignment
[2025-08-23T08:27:15.970+0000] {taskinstance.py:2698} ERROR - Task failed with exception
Traceback (most recent call last):
  File "/opt/airflow/dags/../scripts/fetch_stock_data.py", line 39, in create_stock_table_if_not_exists
    conn = get_db_connection()
  File "/opt/airflow/dags/../scripts/fetch_stock_data.py", line 16, in get_db_connection
    conn = psycopg2.connect(os.getenv('DB_CONNECTION'))
  File "/home/airflow/.local/lib/python3.8/site-packages/psycopg2/__init__.py", line 122, in connect
    conn = _connect(dsn, connection_factory=connection_factory, **kwasync)
psycopg2.OperationalError: connection to server on socket "/var/run/postgresql/.s.PGSQL.5432" failed: No such file or directory
	Is the server running locally and accepting connections on that socket?


During handling of the above exception, another exception occurred:

Traceback (most recent call last):
  File "/home/airflow/.local/lib/python3.8/site-packages/airflow/models/taskinstance.py", line 433, in _execute_task
    result = execute_callable(context=context, **execute_callable_kwargs)
  File "/home/airflow/.local/lib/python3.8/site-packages/airflow/operators/python.py", line 199, in execute
    return_value = self.execute_callable()
  File "/home/airflow/.local/lib/python3.8/site-packages/airflow/operators/python.py", line 216, in execute_callable
    return self.python_callable(*self.op_args, **self.op_kwargs)
  File "/opt/airflow/dags/../scripts/fetch_stock_data.py", line 132, in main
    create_stock_table_if_not_exists()
  File "/opt/airflow/dags/../scripts/fetch_stock_data.py", line 48, in create_stock_table_if_not_exists
    if conn:
UnboundLocalError: local variable 'conn' referenced before assignment
[2025-08-23T08:27:15.993+0000] {taskinstance.py:1138} INFO - Marking task as FAILED. dag_id=stock_data_pipeline, task_id=fetch_and_store_stock_data, execution_date=20250823T070000, start_date=20250823T082715, end_date=20250823T082715
[2025-08-23T08:27:16.022+0000] {standard_task_runner.py:107} ERROR - Failed to execute job 7 for task fetch_and_store_stock_data (local variable 'conn' referenced before assignment; 417)
[2025-08-23T08:27:16.096+0000] {local_task_job_runner.py:234} INFO - Task exited with return code 1
[2025-08-23T08:27:16.142+0000] {taskinstance.py:3280} INFO - 0 downstream tasks scheduled from follow-on schedule check
[2025-08-23T08:48:12.010+0000] {taskinstance.py:1956} INFO - Dependencies all met for dep_context=non-requeueable deps ti=<TaskInstance: stock_data_pipeline.fetch_and_store_stock_data scheduled__2025-08-23T07:00:00+00:00 [queued]>
[2025-08-23T08:48:12.034+0000] {taskinstance.py:1956} INFO - Dependencies all met for dep_context=requeueable deps ti=<TaskInstance: stock_data_pipeline.fetch_and_store_stock_data scheduled__2025-08-23T07:00:00+00:00 [queued]>
[2025-08-23T08:48:12.036+0000] {taskinstance.py:2170} INFO - Starting attempt 2 of 2
[2025-08-23T08:48:12.068+0000] {taskinstance.py:2191} INFO - Executing <Task(PythonOperator): fetch_and_store_stock_data> on 2025-08-23 07:00:00+00:00
[2025-08-23T08:48:12.086+0000] {standard_task_runner.py:60} INFO - Started process 1126 to run task
[2025-08-23T08:48:12.092+0000] {standard_task_runner.py:87} INFO - Running: ['***', 'tasks', 'run', 'stock_data_pipeline', 'fetch_and_store_stock_data', 'scheduled__2025-08-23T07:00:00+00:00', '--job-id', '13', '--raw', '--subdir', 'DAGS_FOLDER/stock_pipeline.py', '--cfg-path', '/tmp/tmppfu0h4kx']
[2025-08-23T08:48:12.097+0000] {standard_task_runner.py:88} INFO - Job 13: Subtask fetch_and_store_stock_data
[2025-08-23T08:48:12.132+0000] {logging_mixin.py:188} WARNING - /home/***/.local/lib/python3.8/site-packages/***/settings.py:194 DeprecationWarning: The sql_alchemy_conn option in [core] has been moved to the sql_alchemy_conn option in [database] - the old setting has been used, but please update your config.
[2025-08-23T08:48:12.234+0000] {task_command.py:423} INFO - Running <TaskInstance: stock_data_pipeline.fetch_and_store_stock_data scheduled__2025-08-23T07:00:00+00:00 [running]> on host e4d6e44b2134
[2025-08-23T08:48:12.746+0000] {taskinstance.py:2480} INFO - Exporting env vars: AIRFLOW_CTX_DAG_OWNER='***' AIRFLOW_CTX_DAG_ID='stock_data_pipeline' AIRFLOW_CTX_TASK_ID='fetch_and_store_stock_data' AIRFLOW_CTX_EXECUTION_DATE='2025-08-23T07:00:00+00:00' AIRFLOW_CTX_TRY_NUMBER='2' AIRFLOW_CTX_DAG_RUN_ID='scheduled__2025-08-23T07:00:00+00:00'
[2025-08-23T08:48:12.749+0000] {fetch_stock_data.py:19} ERROR - Database connection failed: connection to server on socket "/var/run/postgresql/.s.PGSQL.5432" failed: No such file or directory
	Is the server running locally and accepting connections on that socket?

[2025-08-23T08:48:12.751+0000] {fetch_stock_data.py:45} ERROR - Error creating table: connection to server on socket "/var/run/postgresql/.s.PGSQL.5432" failed: No such file or directory
	Is the server running locally and accepting connections on that socket?

[2025-08-23T08:48:12.752+0000] {fetch_stock_data.py:146} ERROR - Pipeline failed: local variable 'conn' referenced before assignment
[2025-08-23T08:48:12.753+0000] {taskinstance.py:2698} ERROR - Task failed with exception
Traceback (most recent call last):
  File "/opt/airflow/dags/../scripts/fetch_stock_data.py", line 39, in create_stock_table_if_not_exists
    conn = get_db_connection()
  File "/opt/airflow/dags/../scripts/fetch_stock_data.py", line 16, in get_db_connection
    conn = psycopg2.connect(os.getenv('DB_CONNECTION'))
  File "/home/airflow/.local/lib/python3.8/site-packages/psycopg2/__init__.py", line 122, in connect
    conn = _connect(dsn, connection_factory=connection_factory, **kwasync)
psycopg2.OperationalError: connection to server on socket "/var/run/postgresql/.s.PGSQL.5432" failed: No such file or directory
	Is the server running locally and accepting connections on that socket?


During handling of the above exception, another exception occurred:

Traceback (most recent call last):
  File "/home/airflow/.local/lib/python3.8/site-packages/airflow/models/taskinstance.py", line 433, in _execute_task
    result = execute_callable(context=context, **execute_callable_kwargs)
  File "/home/airflow/.local/lib/python3.8/site-packages/airflow/operators/python.py", line 199, in execute
    return_value = self.execute_callable()
  File "/home/airflow/.local/lib/python3.8/site-packages/airflow/operators/python.py", line 216, in execute_callable
    return self.python_callable(*self.op_args, **self.op_kwargs)
  File "/opt/airflow/dags/../scripts/fetch_stock_data.py", line 132, in main
    create_stock_table_if_not_exists()
  File "/opt/airflow/dags/../scripts/fetch_stock_data.py", line 48, in create_stock_table_if_not_exists
    if conn:
UnboundLocalError: local variable 'conn' referenced before assignment
[2025-08-23T08:48:12.777+0000] {taskinstance.py:1138} INFO - Marking task as FAILED. dag_id=stock_data_pipeline, task_id=fetch_and_store_stock_data, execution_date=20250823T070000, start_date=20250823T084812, end_date=20250823T084812
[2025-08-23T08:48:12.798+0000] {standard_task_runner.py:107} ERROR - Failed to execute job 13 for task fetch_and_store_stock_data (local variable 'conn' referenced before assignment; 1126)
[2025-08-23T08:48:12.870+0000] {local_task_job_runner.py:234} INFO - Task exited with return code 1
[2025-08-23T08:48:12.912+0000] {taskinstance.py:3280} INFO - 0 downstream tasks scheduled from follow-on schedule check
