[2025-08-23T09:43:48.321+0000] {taskinstance.py:1956} INFO - Dependencies all met for dep_context=non-requeueable deps ti=<TaskInstance: stock_data_pipeline.fetch_and_store_stock_data manual__2025-08-23T09:38:32.027296+00:00 [queued]>
[2025-08-23T09:43:48.353+0000] {taskinstance.py:1956} INFO - Dependencies all met for dep_context=requeueable deps ti=<TaskInstance: stock_data_pipeline.fetch_and_store_stock_data manual__2025-08-23T09:38:32.027296+00:00 [queued]>
[2025-08-23T09:43:48.354+0000] {taskinstance.py:2170} INFO - Starting attempt 1 of 2
[2025-08-23T09:43:48.399+0000] {taskinstance.py:2191} INFO - Executing <Task(PythonOperator): fetch_and_store_stock_data> on 2025-08-23 09:38:32.027296+00:00
[2025-08-23T09:43:48.428+0000] {standard_task_runner.py:60} INFO - Started process 596 to run task
[2025-08-23T09:43:48.440+0000] {standard_task_runner.py:87} INFO - Running: ['***', 'tasks', 'run', 'stock_data_pipeline', 'fetch_and_store_stock_data', 'manual__2025-08-23T09:38:32.027296+00:00', '--job-id', '18', '--raw', '--subdir', 'DAGS_FOLDER/stock_pipeline.py', '--cfg-path', '/tmp/tmpt4f92owu']
[2025-08-23T09:43:48.449+0000] {standard_task_runner.py:88} INFO - Job 18: Subtask fetch_and_store_stock_data
[2025-08-23T09:43:48.506+0000] {logging_mixin.py:188} WARNING - /home/***/.local/lib/python3.8/site-packages/***/settings.py:194 DeprecationWarning: The sql_alchemy_conn option in [core] has been moved to the sql_alchemy_conn option in [database] - the old setting has been used, but please update your config.
[2025-08-23T09:43:48.652+0000] {task_command.py:423} INFO - Running <TaskInstance: stock_data_pipeline.fetch_and_store_stock_data manual__2025-08-23T09:38:32.027296+00:00 [running]> on host da219917e864
[2025-08-23T09:43:52.697+0000] {taskinstance.py:2480} INFO - Exporting env vars: AIRFLOW_CTX_DAG_OWNER='***' AIRFLOW_CTX_DAG_ID='stock_data_pipeline' AIRFLOW_CTX_TASK_ID='fetch_and_store_stock_data' AIRFLOW_CTX_EXECUTION_DATE='2025-08-23T09:38:32.027296+00:00' AIRFLOW_CTX_TRY_NUMBER='1' AIRFLOW_CTX_DAG_RUN_ID='manual__2025-08-23T09:38:32.027296+00:00'
[2025-08-23T09:43:52.704+0000] {fetch_stock_data.py:19} ERROR - Database connection failed: connection to server on socket "/var/run/postgresql/.s.PGSQL.5432" failed: No such file or directory
	Is the server running locally and accepting connections on that socket?

[2025-08-23T09:43:52.706+0000] {fetch_stock_data.py:45} ERROR - Error creating table: connection to server on socket "/var/run/postgresql/.s.PGSQL.5432" failed: No such file or directory
	Is the server running locally and accepting connections on that socket?

[2025-08-23T09:43:52.708+0000] {fetch_stock_data.py:146} ERROR - Pipeline failed: local variable 'conn' referenced before assignment
[2025-08-23T09:43:52.711+0000] {taskinstance.py:2698} ERROR - Task failed with exception
Traceback (most recent call last):
  File "/opt/airflow/dags/../scripts/fetch_stock_data.py", line 39, in create_stock_table_if_not_exists
    conn = get_db_connection()
  File "/opt/airflow/dags/../scripts/fetch_stock_data.py", line 16, in get_db_connection
    conn = psycopg2.connect(os.getenv('DB_CONNECTION'))
  File "/home/airflow/.local/lib/python3.8/site-packages/psycopg2/__init__.py", line 122, in connect
    conn = _connect(dsn, connection_factory=connection_factory, **kwasync)
psycopg2.OperationalError: connection to server on socket "/var/run/postgresql/.s.PGSQL.5432" failed: No such file or directory
	Is the server running locally and accepting connections on that socket?


During handling of the above exception, another exception occurred:

Traceback (most recent call last):
  File "/home/airflow/.local/lib/python3.8/site-packages/airflow/models/taskinstance.py", line 433, in _execute_task
    result = execute_callable(context=context, **execute_callable_kwargs)
  File "/home/airflow/.local/lib/python3.8/site-packages/airflow/operators/python.py", line 199, in execute
    return_value = self.execute_callable()
  File "/home/airflow/.local/lib/python3.8/site-packages/airflow/operators/python.py", line 216, in execute_callable
    return self.python_callable(*self.op_args, **self.op_kwargs)
  File "/opt/airflow/dags/../scripts/fetch_stock_data.py", line 132, in main
    create_stock_table_if_not_exists()
  File "/opt/airflow/dags/../scripts/fetch_stock_data.py", line 48, in create_stock_table_if_not_exists
    if conn:
UnboundLocalError: local variable 'conn' referenced before assignment
[2025-08-23T09:43:52.773+0000] {taskinstance.py:1138} INFO - Marking task as UP_FOR_RETRY. dag_id=stock_data_pipeline, task_id=fetch_and_store_stock_data, execution_date=20250823T093832, start_date=20250823T094348, end_date=20250823T094352
[2025-08-23T09:43:52.820+0000] {standard_task_runner.py:107} ERROR - Failed to execute job 18 for task fetch_and_store_stock_data (local variable 'conn' referenced before assignment; 596)
[2025-08-23T09:43:52.919+0000] {local_task_job_runner.py:234} INFO - Task exited with return code 1
[2025-08-23T09:43:52.987+0000] {taskinstance.py:3280} INFO - 0 downstream tasks scheduled from follow-on schedule check
